[2023-12-22 00:00:04,078] {taskinstance.py:851} INFO - Dependencies all met for <TaskInstance: dag_with_python_weather_v01.fill 2023-12-21T23:00:00+00:00 [queued]>
[2023-12-22 00:00:04,121] {taskinstance.py:851} INFO - Dependencies all met for <TaskInstance: dag_with_python_weather_v01.fill 2023-12-21T23:00:00+00:00 [queued]>
[2023-12-22 00:00:04,122] {taskinstance.py:1042} INFO - 
--------------------------------------------------------------------------------
[2023-12-22 00:00:04,122] {taskinstance.py:1043} INFO - Starting attempt 1 of 1
[2023-12-22 00:00:04,126] {taskinstance.py:1044} INFO - 
--------------------------------------------------------------------------------
[2023-12-22 00:00:04,162] {taskinstance.py:1063} INFO - Executing <Task(PythonOperator): fill> on 2023-12-21T23:00:00+00:00
[2023-12-22 00:00:04,199] {standard_task_runner.py:52} INFO - Started process 14778 to run task
[2023-12-22 00:00:04,224] {standard_task_runner.py:76} INFO - Running: ['airflow', 'tasks', 'run', 'dag_with_python_weather_v01', 'fill', '2023-12-21T23:00:00+00:00', '--job-id', '234', '--pool', 'default_pool', '--raw', '--subdir', 'DAGS_FOLDER/dag_with_python_weather.py', '--cfg-path', '/tmp/tmpfq0at2pg', '--error-file', '/tmp/tmpw00o5g0p']
[2023-12-22 00:00:04,238] {standard_task_runner.py:77} INFO - Job 234: Subtask fill
[2023-12-22 00:00:04,547] {logging_mixin.py:104} INFO - Running <TaskInstance: dag_with_python_weather_v01.fill 2023-12-21T23:00:00+00:00 [running]> on host 5f3722f1fc3b
[2023-12-22 00:00:04,991] {taskinstance.py:1257} INFO - Exporting the following env vars:
AIRFLOW_CTX_DAG_OWNER=ggoni
AIRFLOW_CTX_DAG_ID=dag_with_python_weather_v01
AIRFLOW_CTX_TASK_ID=fill
AIRFLOW_CTX_EXECUTION_DATE=2023-12-21T23:00:00+00:00
AIRFLOW_CTX_DAG_RUN_ID=scheduled__2023-12-21T23:00:00+00:00
[2023-12-22 00:00:10,859] {logging_mixin.py:104} INFO - Error making API call: 502 Server Error: Bad Gateway for url: http://api.weatherapi.com/v1/current.json?key=ee61f61470a04320b77161124231012&q=Quilpu%C3%A9
[2023-12-22 00:00:10,864] {taskinstance.py:1455} ERROR - 'NoneType' object is not subscriptable
Traceback (most recent call last):
  File "/home/airflow/.local/lib/python3.6/site-packages/airflow/models/taskinstance.py", line 1112, in _run_raw_task
    self._prepare_and_execute_task_with_callbacks(context, task)
  File "/home/airflow/.local/lib/python3.6/site-packages/airflow/models/taskinstance.py", line 1285, in _prepare_and_execute_task_with_callbacks
    result = self._execute_task(context, task_copy)
  File "/home/airflow/.local/lib/python3.6/site-packages/airflow/models/taskinstance.py", line 1315, in _execute_task
    result = task_copy.execute(context=context)
  File "/home/airflow/.local/lib/python3.6/site-packages/airflow/operators/python.py", line 117, in execute
    return_value = self.execute_callable()
  File "/home/airflow/.local/lib/python3.6/site-packages/airflow/operators/python.py", line 128, in execute_callable
    return self.python_callable(*self.op_args, **self.op_kwargs)
  File "/opt/airflow/dags/dag_with_python_weather.py", line 83, in fill
    my_tuple = get_data(location)
  File "/opt/airflow/dags/dag_with_python_weather.py", line 70, in get_data
    loc_json['current']['last_updated_epoch']), loc_json['current']['temp_c']
TypeError: 'NoneType' object is not subscriptable
[2023-12-22 00:00:10,890] {taskinstance.py:1503} INFO - Marking task as FAILED. dag_id=dag_with_python_weather_v01, task_id=fill, execution_date=20231221T230000, start_date=20231222T000004, end_date=20231222T000010
[2023-12-22 00:00:11,004] {local_task_job.py:146} INFO - Task exited with return code 1
