[2023-12-13 16:39:37,179] {taskinstance.py:851} INFO - Dependencies all met for <TaskInstance: dag_with_python_weather_v01.fill 2023-12-13T16:39:33.224616+00:00 [queued]>
[2023-12-13 16:39:37,228] {taskinstance.py:851} INFO - Dependencies all met for <TaskInstance: dag_with_python_weather_v01.fill 2023-12-13T16:39:33.224616+00:00 [queued]>
[2023-12-13 16:39:37,236] {taskinstance.py:1042} INFO - 
--------------------------------------------------------------------------------
[2023-12-13 16:39:37,245] {taskinstance.py:1043} INFO - Starting attempt 1 of 1
[2023-12-13 16:39:37,253] {taskinstance.py:1044} INFO - 
--------------------------------------------------------------------------------
[2023-12-13 16:39:37,311] {taskinstance.py:1063} INFO - Executing <Task(PythonOperator): fill> on 2023-12-13T16:39:33.224616+00:00
[2023-12-13 16:39:37,326] {standard_task_runner.py:52} INFO - Started process 6575 to run task
[2023-12-13 16:39:37,369] {standard_task_runner.py:76} INFO - Running: ['airflow', 'tasks', 'run', 'dag_with_python_weather_v01', 'fill', '2023-12-13T16:39:33.224616+00:00', '--job-id', '137', '--pool', 'default_pool', '--raw', '--subdir', 'DAGS_FOLDER/dag_with_python_weather.py', '--cfg-path', '/tmp/tmpep5r_270', '--error-file', '/tmp/tmpm3bu9nbe']
[2023-12-13 16:39:37,379] {standard_task_runner.py:77} INFO - Job 137: Subtask fill
[2023-12-13 16:39:37,575] {logging_mixin.py:104} INFO - Running <TaskInstance: dag_with_python_weather_v01.fill 2023-12-13T16:39:33.224616+00:00 [running]> on host 40570a32c2c3
[2023-12-13 16:39:37,717] {taskinstance.py:1257} INFO - Exporting the following env vars:
AIRFLOW_CTX_DAG_OWNER=ggoni
AIRFLOW_CTX_DAG_ID=dag_with_python_weather_v01
AIRFLOW_CTX_TASK_ID=fill
AIRFLOW_CTX_EXECUTION_DATE=2023-12-13T16:39:33.224616+00:00
AIRFLOW_CTX_DAG_RUN_ID=manual__2023-12-13T16:39:33.224616+00:00
[2023-12-13 16:39:38,989] {taskinstance.py:1455} ERROR - [Errno 2] No such file or directory: '../data/mediciones.csv'
Traceback (most recent call last):
  File "/home/airflow/.local/lib/python3.6/site-packages/airflow/models/taskinstance.py", line 1112, in _run_raw_task
    self._prepare_and_execute_task_with_callbacks(context, task)
  File "/home/airflow/.local/lib/python3.6/site-packages/airflow/models/taskinstance.py", line 1285, in _prepare_and_execute_task_with_callbacks
    result = self._execute_task(context, task_copy)
  File "/home/airflow/.local/lib/python3.6/site-packages/airflow/models/taskinstance.py", line 1315, in _execute_task
    result = task_copy.execute(context=context)
  File "/home/airflow/.local/lib/python3.6/site-packages/airflow/operators/python.py", line 117, in execute
    return_value = self.execute_callable()
  File "/home/airflow/.local/lib/python3.6/site-packages/airflow/operators/python.py", line 128, in execute_callable
    return self.python_callable(*self.op_args, **self.op_kwargs)
  File "/opt/airflow/dags/dag_with_python_weather.py", line 85, in fill
    log_data('../data/mediciones.csv', newline)
  File "/opt/airflow/dags/dag_with_python_weather.py", line 76, in log_data
    with open(file_path, 'a', newline='') as csv_file:
FileNotFoundError: [Errno 2] No such file or directory: '../data/mediciones.csv'
[2023-12-13 16:39:39,001] {taskinstance.py:1503} INFO - Marking task as FAILED. dag_id=dag_with_python_weather_v01, task_id=fill, execution_date=20231213T163933, start_date=20231213T163937, end_date=20231213T163939
[2023-12-13 16:39:39,096] {local_task_job.py:146} INFO - Task exited with return code 1
