[2023-12-13 16:32:19,953] {taskinstance.py:851} INFO - Dependencies all met for <TaskInstance: dag_with_python_weather_v01.fill 2021-10-15T00:00:00+00:00 [queued]>
[2023-12-13 16:32:20,075] {taskinstance.py:851} INFO - Dependencies all met for <TaskInstance: dag_with_python_weather_v01.fill 2021-10-15T00:00:00+00:00 [queued]>
[2023-12-13 16:32:20,076] {taskinstance.py:1042} INFO - 
--------------------------------------------------------------------------------
[2023-12-13 16:32:20,076] {taskinstance.py:1043} INFO - Starting attempt 1 of 1
[2023-12-13 16:32:20,077] {taskinstance.py:1044} INFO - 
--------------------------------------------------------------------------------
[2023-12-13 16:32:20,166] {taskinstance.py:1063} INFO - Executing <Task(PythonOperator): fill> on 2021-10-15T00:00:00+00:00
[2023-12-13 16:32:20,190] {standard_task_runner.py:52} INFO - Started process 4519 to run task
[2023-12-13 16:32:20,258] {standard_task_runner.py:76} INFO - Running: ['airflow', 'tasks', 'run', 'dag_with_python_weather_v01', 'fill', '2021-10-15T00:00:00+00:00', '--job-id', '77', '--pool', 'default_pool', '--raw', '--subdir', 'DAGS_FOLDER/dag_with_python_weather.py', '--cfg-path', '/tmp/tmp_bjn00rg', '--error-file', '/tmp/tmpzbz7sgql']
[2023-12-13 16:32:20,273] {standard_task_runner.py:77} INFO - Job 77: Subtask fill
[2023-12-13 16:32:20,549] {logging_mixin.py:104} INFO - Running <TaskInstance: dag_with_python_weather_v01.fill 2021-10-15T00:00:00+00:00 [running]> on host 40570a32c2c3
[2023-12-13 16:32:20,876] {taskinstance.py:1257} INFO - Exporting the following env vars:
AIRFLOW_CTX_DAG_OWNER=ggoni
AIRFLOW_CTX_DAG_ID=dag_with_python_weather_v01
AIRFLOW_CTX_TASK_ID=fill
AIRFLOW_CTX_EXECUTION_DATE=2021-10-15T00:00:00+00:00
AIRFLOW_CTX_DAG_RUN_ID=scheduled__2021-10-15T00:00:00+00:00
[2023-12-13 16:32:20,882] {taskinstance.py:1455} ERROR - name 'locations' is not defined
Traceback (most recent call last):
  File "/home/airflow/.local/lib/python3.6/site-packages/airflow/models/taskinstance.py", line 1112, in _run_raw_task
    self._prepare_and_execute_task_with_callbacks(context, task)
  File "/home/airflow/.local/lib/python3.6/site-packages/airflow/models/taskinstance.py", line 1285, in _prepare_and_execute_task_with_callbacks
    result = self._execute_task(context, task_copy)
  File "/home/airflow/.local/lib/python3.6/site-packages/airflow/models/taskinstance.py", line 1315, in _execute_task
    result = task_copy.execute(context=context)
  File "/home/airflow/.local/lib/python3.6/site-packages/airflow/operators/python.py", line 117, in execute
    return_value = self.execute_callable()
  File "/home/airflow/.local/lib/python3.6/site-packages/airflow/operators/python.py", line 128, in execute_callable
    return self.python_callable(*self.op_args, **self.op_kwargs)
  File "/opt/airflow/dags/dag_with_python_weather.py", line 74, in fill
    for location in locations:
NameError: name 'locations' is not defined
[2023-12-13 16:32:20,908] {taskinstance.py:1503} INFO - Marking task as FAILED. dag_id=dag_with_python_weather_v01, task_id=fill, execution_date=20211015T000000, start_date=20231213T163219, end_date=20231213T163220
[2023-12-13 16:32:21,034] {local_task_job.py:146} INFO - Task exited with return code 1
