[2023-12-13 16:31:03,392] {taskinstance.py:851} INFO - Dependencies all met for <TaskInstance: dag_with_python_weather_v01.fill 2023-12-13T16:30:17.197628+00:00 [queued]>
[2023-12-13 16:31:03,719] {taskinstance.py:851} INFO - Dependencies all met for <TaskInstance: dag_with_python_weather_v01.fill 2023-12-13T16:30:17.197628+00:00 [queued]>
[2023-12-13 16:31:03,756] {taskinstance.py:1042} INFO - 
--------------------------------------------------------------------------------
[2023-12-13 16:31:03,778] {taskinstance.py:1043} INFO - Starting attempt 1 of 1
[2023-12-13 16:31:03,842] {taskinstance.py:1044} INFO - 
--------------------------------------------------------------------------------
[2023-12-13 16:31:04,270] {taskinstance.py:1063} INFO - Executing <Task(PythonOperator): fill> on 2023-12-13T16:30:17.197628+00:00
[2023-12-13 16:31:04,850] {standard_task_runner.py:52} INFO - Started process 4137 to run task
[2023-12-13 16:31:05,283] {standard_task_runner.py:76} INFO - Running: ['airflow', 'tasks', 'run', 'dag_with_python_weather_v01', 'fill', '2023-12-13T16:30:17.197628+00:00', '--job-id', '8', '--pool', 'default_pool', '--raw', '--subdir', 'DAGS_FOLDER/dag_with_python_weather.py', '--cfg-path', '/tmp/tmp9q9iojre', '--error-file', '/tmp/tmp_dij6o7y']
[2023-12-13 16:31:05,657] {standard_task_runner.py:77} INFO - Job 8: Subtask fill
[2023-12-13 16:31:13,830] {logging_mixin.py:104} INFO - Running <TaskInstance: dag_with_python_weather_v01.fill 2023-12-13T16:30:17.197628+00:00 [running]> on host 40570a32c2c3
[2023-12-13 16:31:18,871] {taskinstance.py:1257} INFO - Exporting the following env vars:
AIRFLOW_CTX_DAG_OWNER=ggoni
AIRFLOW_CTX_DAG_ID=dag_with_python_weather_v01
AIRFLOW_CTX_TASK_ID=fill
AIRFLOW_CTX_EXECUTION_DATE=2023-12-13T16:30:17.197628+00:00
AIRFLOW_CTX_DAG_RUN_ID=manual__2023-12-13T16:30:17.197628+00:00
[2023-12-13 16:31:18,902] {taskinstance.py:1455} ERROR - name 'locations' is not defined
Traceback (most recent call last):
  File "/home/airflow/.local/lib/python3.6/site-packages/airflow/models/taskinstance.py", line 1112, in _run_raw_task
    self._prepare_and_execute_task_with_callbacks(context, task)
  File "/home/airflow/.local/lib/python3.6/site-packages/airflow/models/taskinstance.py", line 1285, in _prepare_and_execute_task_with_callbacks
    result = self._execute_task(context, task_copy)
  File "/home/airflow/.local/lib/python3.6/site-packages/airflow/models/taskinstance.py", line 1315, in _execute_task
    result = task_copy.execute(context=context)
  File "/home/airflow/.local/lib/python3.6/site-packages/airflow/operators/python.py", line 117, in execute
    return_value = self.execute_callable()
  File "/home/airflow/.local/lib/python3.6/site-packages/airflow/operators/python.py", line 128, in execute_callable
    return self.python_callable(*self.op_args, **self.op_kwargs)
  File "/opt/airflow/dags/dag_with_python_weather.py", line 74, in fill
    for location in locations:
NameError: name 'locations' is not defined
[2023-12-13 16:31:18,959] {taskinstance.py:1503} INFO - Marking task as FAILED. dag_id=dag_with_python_weather_v01, task_id=fill, execution_date=20231213T163017, start_date=20231213T163103, end_date=20231213T163118
[2023-12-13 16:31:20,881] {local_task_job.py:146} INFO - Task exited with return code 1
