[2023-12-13 16:33:36,861] {taskinstance.py:851} INFO - Dependencies all met for <TaskInstance: dag_with_python_weather_v01.fill 2023-12-13T11:00:00+00:00 [queued]>
[2023-12-13 16:33:36,929] {taskinstance.py:851} INFO - Dependencies all met for <TaskInstance: dag_with_python_weather_v01.fill 2023-12-13T11:00:00+00:00 [queued]>
[2023-12-13 16:33:36,930] {taskinstance.py:1042} INFO - 
--------------------------------------------------------------------------------
[2023-12-13 16:33:36,931] {taskinstance.py:1043} INFO - Starting attempt 1 of 1
[2023-12-13 16:33:36,932] {taskinstance.py:1044} INFO - 
--------------------------------------------------------------------------------
[2023-12-13 16:33:37,000] {taskinstance.py:1063} INFO - Executing <Task(PythonOperator): fill> on 2023-12-13T11:00:00+00:00
[2023-12-13 16:33:37,023] {standard_task_runner.py:52} INFO - Started process 4957 to run task
[2023-12-13 16:33:37,078] {standard_task_runner.py:76} INFO - Running: ['airflow', 'tasks', 'run', 'dag_with_python_weather_v01', 'fill', '2023-12-13T11:00:00+00:00', '--job-id', '131', '--pool', 'default_pool', '--raw', '--subdir', 'DAGS_FOLDER/dag_with_python_weather.py', '--cfg-path', '/tmp/tmpm_4ydn5j', '--error-file', '/tmp/tmpif0zrc6_']
[2023-12-13 16:33:37,087] {standard_task_runner.py:77} INFO - Job 131: Subtask fill
[2023-12-13 16:33:37,520] {logging_mixin.py:104} INFO - Running <TaskInstance: dag_with_python_weather_v01.fill 2023-12-13T11:00:00+00:00 [running]> on host 40570a32c2c3
[2023-12-13 16:33:38,006] {taskinstance.py:1257} INFO - Exporting the following env vars:
AIRFLOW_CTX_DAG_OWNER=ggoni
AIRFLOW_CTX_DAG_ID=dag_with_python_weather_v01
AIRFLOW_CTX_TASK_ID=fill
AIRFLOW_CTX_EXECUTION_DATE=2023-12-13T11:00:00+00:00
AIRFLOW_CTX_DAG_RUN_ID=scheduled__2023-12-13T11:00:00+00:00
[2023-12-13 16:33:38,010] {taskinstance.py:1455} ERROR - name 'locations' is not defined
Traceback (most recent call last):
  File "/home/airflow/.local/lib/python3.6/site-packages/airflow/models/taskinstance.py", line 1112, in _run_raw_task
    self._prepare_and_execute_task_with_callbacks(context, task)
  File "/home/airflow/.local/lib/python3.6/site-packages/airflow/models/taskinstance.py", line 1285, in _prepare_and_execute_task_with_callbacks
    result = self._execute_task(context, task_copy)
  File "/home/airflow/.local/lib/python3.6/site-packages/airflow/models/taskinstance.py", line 1315, in _execute_task
    result = task_copy.execute(context=context)
  File "/home/airflow/.local/lib/python3.6/site-packages/airflow/operators/python.py", line 117, in execute
    return_value = self.execute_callable()
  File "/home/airflow/.local/lib/python3.6/site-packages/airflow/operators/python.py", line 128, in execute_callable
    return self.python_callable(*self.op_args, **self.op_kwargs)
  File "/opt/airflow/dags/dag_with_python_weather.py", line 74, in fill
    for location in locations:
NameError: name 'locations' is not defined
[2023-12-13 16:33:38,058] {taskinstance.py:1503} INFO - Marking task as FAILED. dag_id=dag_with_python_weather_v01, task_id=fill, execution_date=20231213T110000, start_date=20231213T163336, end_date=20231213T163338
[2023-12-13 16:33:38,189] {local_task_job.py:146} INFO - Task exited with return code 1
