[2023-12-13 17:00:03,452] {taskinstance.py:851} INFO - Dependencies all met for <TaskInstance: dag_with_python_weather_v01.fill 2023-12-13T16:00:00+00:00 [queued]>
[2023-12-13 17:00:03,476] {taskinstance.py:851} INFO - Dependencies all met for <TaskInstance: dag_with_python_weather_v01.fill 2023-12-13T16:00:00+00:00 [queued]>
[2023-12-13 17:00:03,477] {taskinstance.py:1042} INFO - 
--------------------------------------------------------------------------------
[2023-12-13 17:00:03,477] {taskinstance.py:1043} INFO - Starting attempt 1 of 1
[2023-12-13 17:00:03,478] {taskinstance.py:1044} INFO - 
--------------------------------------------------------------------------------
[2023-12-13 17:00:03,489] {taskinstance.py:1063} INFO - Executing <Task(PythonOperator): fill> on 2023-12-13T16:00:00+00:00
[2023-12-13 17:00:03,494] {standard_task_runner.py:52} INFO - Started process 3408 to run task
[2023-12-13 17:00:03,498] {standard_task_runner.py:76} INFO - Running: ['airflow', 'tasks', 'run', 'dag_with_python_weather_v01', 'fill', '2023-12-13T16:00:00+00:00', '--job-id', '139', '--pool', 'default_pool', '--raw', '--subdir', 'DAGS_FOLDER/dag_with_python_weather.py', '--cfg-path', '/tmp/tmpwkideyb4', '--error-file', '/tmp/tmpcl83eul1']
[2023-12-13 17:00:03,501] {standard_task_runner.py:77} INFO - Job 139: Subtask fill
[2023-12-13 17:00:03,571] {logging_mixin.py:104} INFO - Running <TaskInstance: dag_with_python_weather_v01.fill 2023-12-13T16:00:00+00:00 [running]> on host 27393a612fb2
[2023-12-13 17:00:03,662] {taskinstance.py:1257} INFO - Exporting the following env vars:
AIRFLOW_CTX_DAG_OWNER=ggoni
AIRFLOW_CTX_DAG_ID=dag_with_python_weather_v01
AIRFLOW_CTX_TASK_ID=fill
AIRFLOW_CTX_EXECUTION_DATE=2023-12-13T16:00:00+00:00
AIRFLOW_CTX_DAG_RUN_ID=scheduled__2023-12-13T16:00:00+00:00
[2023-12-13 17:00:04,844] {taskinstance.py:1455} ERROR - [Errno 2] No such file or directory: '../data/mediciones.csv'
Traceback (most recent call last):
  File "/home/airflow/.local/lib/python3.6/site-packages/airflow/models/taskinstance.py", line 1112, in _run_raw_task
    self._prepare_and_execute_task_with_callbacks(context, task)
  File "/home/airflow/.local/lib/python3.6/site-packages/airflow/models/taskinstance.py", line 1285, in _prepare_and_execute_task_with_callbacks
    result = self._execute_task(context, task_copy)
  File "/home/airflow/.local/lib/python3.6/site-packages/airflow/models/taskinstance.py", line 1315, in _execute_task
    result = task_copy.execute(context=context)
  File "/home/airflow/.local/lib/python3.6/site-packages/airflow/operators/python.py", line 117, in execute
    return_value = self.execute_callable()
  File "/home/airflow/.local/lib/python3.6/site-packages/airflow/operators/python.py", line 128, in execute_callable
    return self.python_callable(*self.op_args, **self.op_kwargs)
  File "/opt/airflow/dags/dag_with_python_weather.py", line 85, in fill
    log_data('../data/mediciones.csv', newline)
  File "/opt/airflow/dags/dag_with_python_weather.py", line 76, in log_data
    with open(file_path, 'a', newline='') as csv_file:
FileNotFoundError: [Errno 2] No such file or directory: '../data/mediciones.csv'
[2023-12-13 17:00:04,850] {taskinstance.py:1503} INFO - Marking task as FAILED. dag_id=dag_with_python_weather_v01, task_id=fill, execution_date=20231213T160000, start_date=20231213T170003, end_date=20231213T170004
[2023-12-13 17:00:04,924] {local_task_job.py:146} INFO - Task exited with return code 1
