[2023-12-13 16:31:41,151] {taskinstance.py:851} INFO - Dependencies all met for <TaskInstance: dag_with_python_weather_v01.fill 2021-10-13T14:00:00+00:00 [queued]>
[2023-12-13 16:31:41,239] {taskinstance.py:851} INFO - Dependencies all met for <TaskInstance: dag_with_python_weather_v01.fill 2021-10-13T14:00:00+00:00 [queued]>
[2023-12-13 16:31:41,243] {taskinstance.py:1042} INFO - 
--------------------------------------------------------------------------------
[2023-12-13 16:31:41,246] {taskinstance.py:1043} INFO - Starting attempt 1 of 1
[2023-12-13 16:31:41,246] {taskinstance.py:1044} INFO - 
--------------------------------------------------------------------------------
[2023-12-13 16:31:41,318] {taskinstance.py:1063} INFO - Executing <Task(PythonOperator): fill> on 2021-10-13T14:00:00+00:00
[2023-12-13 16:31:41,507] {standard_task_runner.py:52} INFO - Started process 4299 to run task
[2023-12-13 16:31:42,300] {standard_task_runner.py:76} INFO - Running: ['airflow', 'tasks', 'run', 'dag_with_python_weather_v01', 'fill', '2021-10-13T14:00:00+00:00', '--job-id', '43', '--pool', 'default_pool', '--raw', '--subdir', 'DAGS_FOLDER/dag_with_python_weather.py', '--cfg-path', '/tmp/tmpln81k4m5', '--error-file', '/tmp/tmp65kebgxw']
[2023-12-13 16:31:43,632] {standard_task_runner.py:77} INFO - Job 43: Subtask fill
[2023-12-13 16:31:45,554] {logging_mixin.py:104} INFO - Running <TaskInstance: dag_with_python_weather_v01.fill 2021-10-13T14:00:00+00:00 [running]> on host 40570a32c2c3
[2023-12-13 16:31:46,296] {taskinstance.py:1257} INFO - Exporting the following env vars:
AIRFLOW_CTX_DAG_OWNER=ggoni
AIRFLOW_CTX_DAG_ID=dag_with_python_weather_v01
AIRFLOW_CTX_TASK_ID=fill
AIRFLOW_CTX_EXECUTION_DATE=2021-10-13T14:00:00+00:00
AIRFLOW_CTX_DAG_RUN_ID=scheduled__2021-10-13T14:00:00+00:00
[2023-12-13 16:31:46,299] {taskinstance.py:1455} ERROR - name 'locations' is not defined
Traceback (most recent call last):
  File "/home/airflow/.local/lib/python3.6/site-packages/airflow/models/taskinstance.py", line 1112, in _run_raw_task
    self._prepare_and_execute_task_with_callbacks(context, task)
  File "/home/airflow/.local/lib/python3.6/site-packages/airflow/models/taskinstance.py", line 1285, in _prepare_and_execute_task_with_callbacks
    result = self._execute_task(context, task_copy)
  File "/home/airflow/.local/lib/python3.6/site-packages/airflow/models/taskinstance.py", line 1315, in _execute_task
    result = task_copy.execute(context=context)
  File "/home/airflow/.local/lib/python3.6/site-packages/airflow/operators/python.py", line 117, in execute
    return_value = self.execute_callable()
  File "/home/airflow/.local/lib/python3.6/site-packages/airflow/operators/python.py", line 128, in execute_callable
    return self.python_callable(*self.op_args, **self.op_kwargs)
  File "/opt/airflow/dags/dag_with_python_weather.py", line 74, in fill
    for location in locations:
NameError: name 'locations' is not defined
[2023-12-13 16:31:46,316] {taskinstance.py:1503} INFO - Marking task as FAILED. dag_id=dag_with_python_weather_v01, task_id=fill, execution_date=20211013T140000, start_date=20231213T163141, end_date=20231213T163146
[2023-12-13 16:31:46,397] {local_task_job.py:146} INFO - Task exited with return code 1
